Workbook

Sheet Panel Summary
A1: ITC327W | PHASE 3: PANEL SUMMARY
A2: Marks are entered on each group's tab. The panel result appears after all seven criteria have been marked by all three lecturers.
A4: Group | B4: Project / Stakeholder | C4: Lecturer 1 /100 | D4: Lecturer 2 /100 | E4: Lecturer 3 /100 | F4: Panel Average /100 | G4: Phase 3 Mark /50 | H4: Marking Status
A5: Group A | B5: =IF('Group A'!F3="","",'Group A'!F3) | C5: =IF('Group A'!G17="","",'Group A'!G17) | D5: =IF('Group A'!H17="","",'Group A'!H17) | E5: =IF('Group A'!I17="","",'Group A'!I17) | F5: =IF('Group A'!J17="","",'Group A'!J17) | G5: =IF('Group A'!J18="","",'Group A'!J18) | H5: ='Group A'!B28 -> 0/3 lecturers complete
A6: Group B | B6: =IF('Group B'!F3="","",'Group B'!F3) | C6: =IF('Group B'!G17="","",'Group B'!G17) | D6: =IF('Group B'!H17="","",'Group B'!H17) | E6: =IF('Group B'!I17="","",'Group B'!I17) | F6: =IF('Group B'!J17="","",'Group B'!J17) | G6: =IF('Group B'!J18="","",'Group B'!J18) | H6: ='Group B'!B28 -> 0/3 lecturers complete
A7: Group C | B7: =IF('Group C'!F3="","",'Group C'!F3) | C7: =IF('Group C'!G17="","",'Group C'!G17) | D7: =IF('Group C'!H17="","",'Group C'!H17) | E7: =IF('Group C'!I17="","",'Group C'!I17) | F7: =IF('Group C'!J17="","",'Group C'!J17) | G7: =IF('Group C'!J18="","",'Group C'!J18) | H7: ='Group C'!B28 -> 0/3 lecturers complete
A8: Group D | B8: =IF('Group D'!F3="","",'Group D'!F3) | C8: =IF('Group D'!G17="","",'Group D'!G17) | D8: =IF('Group D'!H17="","",'Group D'!H17) | E8: =IF('Group D'!I17="","",'Group D'!I17) | F8: =IF('Group D'!J17="","",'Group D'!J17) | G8: =IF('Group D'!J18="","",'Group D'!J18) | H8: ='Group D'!B28 -> 0/3 lecturers complete
A9: Group E | B9: =IF('Group E'!F3="","",'Group E'!F3) | C9: =IF('Group E'!G17="","",'Group E'!G17) | D9: =IF('Group E'!H17="","",'Group E'!H17) | E9: =IF('Group E'!I17="","",'Group E'!I17) | F9: =IF('Group E'!J17="","",'Group E'!J17) | G9: =IF('Group E'!J18="","",'Group E'!J18) | H9: ='Group E'!B28 -> 0/3 lecturers complete
A10: Group F | B10: =IF('Group F'!F3="","",'Group F'!F3) | C10: =IF('Group F'!G17="","",'Group F'!G17) | D10: =IF('Group F'!H17="","",'Group F'!H17) | E10: =IF('Group F'!I17="","",'Group F'!I17) | F10: =IF('Group F'!J17="","",'Group F'!J17) | G10: =IF('Group F'!J18="","",'Group F'!J18) | H10: ='Group F'!B28 -> 0/3 lecturers complete
A11: Group G | B11: =IF('Group G'!F3="","",'Group G'!F3) | C11: =IF('Group G'!G17="","",'Group G'!G17) | D11: =IF('Group G'!H17="","",'Group G'!H17) | E11: =IF('Group G'!I17="","",'Group G'!I17) | F11: =IF('Group G'!J17="","",'Group G'!J17) | G11: =IF('Group G'!J18="","",'Group G'!J18) | H11: ='Group G'!B28 -> 0/3 lecturers complete
A12: Group H | B12: =IF('Group H'!F3="","",'Group H'!F3) | C12: =IF('Group H'!G17="","",'Group H'!G17) | D12: =IF('Group H'!H17="","",'Group H'!H17) | E12: =IF('Group H'!I17="","",'Group H'!I17) | F12: =IF('Group H'!J17="","",'Group H'!J17) | G12: =IF('Group H'!J18="","",'Group H'!J18) | H12: ='Group H'!B28 -> 0/3 lecturers complete
A13: Group I | B13: =IF('Group I'!F3="","",'Group I'!F3) | C13: =IF('Group I'!G17="","",'Group I'!G17) | D13: =IF('Group I'!H17="","",'Group I'!H17) | E13: =IF('Group I'!I17="","",'Group I'!I17) | F13: =IF('Group I'!J17="","",'Group I'!J17) | G13: =IF('Group I'!J18="","",'Group I'!J18) | H13: ='Group I'!B28 -> 0/3 lecturers complete
A14: Group J | B14: =IF('Group J'!F3="","",'Group J'!F3) | C14: =IF('Group J'!G17="","",'Group J'!G17) | D14: =IF('Group J'!H17="","",'Group J'!H17) | E14: =IF('Group J'!I17="","",'Group J'!I17) | F14: =IF('Group J'!J17="","",'Group J'!J17) | G14: =IF('Group J'!J18="","",'Group J'!J18) | H14: ='Group J'!B28 -> 0/3 lecturers complete
A15: Group K | B15: =IF('Group K'!F3="","",'Group K'!F3) | C15: =IF('Group K'!G17="","",'Group K'!G17) | D15: =IF('Group K'!H17="","",'Group K'!H17) | E15: =IF('Group K'!I17="","",'Group K'!I17) | F15: =IF('Group K'!J17="","",'Group K'!J17) | G15: =IF('Group K'!J18="","",'Group K'!J18) | H15: ='Group K'!B28 -> 0/3 lecturers complete
A16: Group L | B16: =IF('Group L'!F3="","",'Group L'!F3) | C16: =IF('Group L'!G17="","",'Group L'!G17) | D16: =IF('Group L'!H17="","",'Group L'!H17) | E16: =IF('Group L'!I17="","",'Group L'!I17) | F16: =IF('Group L'!J17="","",'Group L'!J17) | G16: =IF('Group L'!J18="","",'Group L'!J18) | H16: ='Group L'!B28 -> 0/3 lecturers complete
A17: Group M | B17: =IF('Group M'!F3="","",'Group M'!F3) | C17: =IF('Group M'!G17="","",'Group M'!G17) | D17: =IF('Group M'!H17="","",'Group M'!H17) | E17: =IF('Group M'!I17="","",'Group M'!I17) | F17: =IF('Group M'!J17="","",'Group M'!J17) | G17: =IF('Group M'!J18="","",'Group M'!J18) | H17: ='Group M'!B28 -> 0/3 lecturers complete
A18: Group N | B18: =IF('Group N'!F3="","",'Group N'!F3) | C18: =IF('Group N'!G17="","",'Group N'!G17) | D18: =IF('Group N'!H17="","",'Group N'!H17) | E18: =IF('Group N'!I17="","",'Group N'!I17) | F18: =IF('Group N'!J17="","",'Group N'!J17) | G18: =IF('Group N'!J18="","",'Group N'!J18) | H18: ='Group N'!B28 -> 0/3 lecturers complete
A19: Group O | B19: =IF('Group O'!F3="","",'Group O'!F3) | C19: =IF('Group O'!G17="","",'Group O'!G17) | D19: =IF('Group O'!H17="","",'Group O'!H17) | E19: =IF('Group O'!I17="","",'Group O'!I17) | F19: =IF('Group O'!J17="","",'Group O'!J17) | G19: =IF('Group O'!J18="","",'Group O'!J18) | H19: ='Group O'!B28 -> 0/3 lecturers complete
A20: Group P | B20: =IF('Group P'!F3="","",'Group P'!F3) | C20: =IF('Group P'!G17="","",'Group P'!G17) | D20: =IF('Group P'!H17="","",'Group P'!H17) | E20: =IF('Group P'!I17="","",'Group P'!I17) | F20: =IF('Group P'!J17="","",'Group P'!J17) | G20: =IF('Group P'!J18="","",'Group P'!J18) | H20: ='Group P'!B28 -> 0/3 lecturers complete
A21: Group Q | B21: =IF('Group Q'!F3="","",'Group Q'!F3) | C21: =IF('Group Q'!G17="","",'Group Q'!G17) | D21: =IF('Group Q'!H17="","",'Group Q'!H17) | E21: =IF('Group Q'!I17="","",'Group Q'!I17) | F21: =IF('Group Q'!J17="","",'Group Q'!J17) | G21: =IF('Group Q'!J18="","",'Group Q'!J18) | H21: ='Group Q'!B28 -> 0/3 lecturers complete
A22: Group R | B22: =IF('Group R'!F3="","",'Group R'!F3) | C22: =IF('Group R'!G17="","",'Group R'!G17) | D22: =IF('Group R'!H17="","",'Group R'!H17) | E22: =IF('Group R'!I17="","",'Group R'!I17) | F22: =IF('Group R'!J17="","",'Group R'!J17) | G22: =IF('Group R'!J18="","",'Group R'!J18) | H22: ='Group R'!B28 -> 0/3 lecturers complete
A23: Group S | B23: =IF('Group S'!F3="","",'Group S'!F3) | C23: =IF('Group S'!G17="","",'Group S'!G17) | D23: =IF('Group S'!H17="","",'Group S'!H17) | E23: =IF('Group S'!I17="","",'Group S'!I17) | F23: =IF('Group S'!J17="","",'Group S'!J17) | G23: =IF('Group S'!J18="","",'Group S'!J18) | H23: ='Group S'!B28 -> 0/3 lecturers complete
A24: Group T | B24: =IF('Group T'!F3="","",'Group T'!F3) | C24: =IF('Group T'!G17="","",'Group T'!G17) | D24: =IF('Group T'!H17="","",'Group T'!H17) | E24: =IF('Group T'!I17="","",'Group T'!I17) | F24: =IF('Group T'!J17="","",'Group T'!J17) | G24: =IF('Group T'!J18="","",'Group T'!J18) | H24: ='Group T'!B28 -> 0/3 lecturers complete
A25: Group U | B25: =IF('Group U'!F3="","",'Group U'!F3) | C25: =IF('Group U'!G16="","",'Group U'!G16) | D25: =IF('Group U'!H16="","",'Group U'!H16) | E25: =IF('Group U'!I16="","",'Group U'!I16) | F25: =IF('Group U'!J16="","",'Group U'!J16) | G25: =IF('Group U'!J17="","",'Group U'!J17) | H25: ='Group U'!B27 -> 0/3 lecturers complete
A26: Group V | B26: =IF('Group V'!F2="","",'Group V'!F2) | C26: =IF('Group V'!G15="","",'Group V'!G15) | D26: =IF('Group V'!H15="","",'Group V'!H15) | E26: =IF('Group V'!I15="","",'Group V'!I15) | F26: =IF('Group V'!J15="","",'Group V'!J15) | G26: =IF('Group V'!J16="","",'Group V'!J16) | H26: ='Group V'!B26 -> 0/3 lecturers complete
A27: Group W | B27: =IF('Group W'!F2="","",'Group W'!F2) | C27: =IF('Group W'!G15="","",'Group W'!G15) | D27: =IF('Group W'!H15="","",'Group W'!H15) | E27: =IF('Group W'!I15="","",'Group W'!I15) | F27: =IF('Group W'!J15="","",'Group W'!J15) | G27: =IF('Group W'!J16="","",'Group W'!J16) | H27: ='Group W'!B26 -> 0/3 lecturers complete
A28: Group X | B28: =IF('Group X'!F2="","",'Group X'!F2) | C28: =IF('Group X'!G15="","",'Group X'!G15) | D28: =IF('Group X'!H15="","",'Group X'!H15) | E28: =IF('Group X'!I15="","",'Group X'!I15) | F28: =IF('Group X'!J15="","",'Group X'!J15) | G28: =IF('Group X'!J16="","",'Group X'!J16) | H28: ='Group X'!B26 -> 0/3 lecturers complete
A29: Group Y | B29: =IF('Group Y'!F2="","",'Group Y'!F2) | C29: =IF('Group Y'!G15="","",'Group Y'!G15) | D29: =IF('Group Y'!H15="","",'Group Y'!H15) | E29: =IF('Group Y'!I15="","",'Group Y'!I15) | F29: =IF('Group Y'!J15="","",'Group Y'!J15) | G29: =IF('Group Y'!J16="","",'Group Y'!J16) | H29: ='Group Y'!B26 -> 0/3 lecturers complete
A30: Group Z | B30: =IF('Group Z'!F2="","",'Group Z'!F2) | C30: =IF('Group Z'!G15="","",'Group Z'!G15) | D30: =IF('Group Z'!H15="","",'Group Z'!H15) | E30: =IF('Group Z'!I15="","",'Group Z'!I15) | F30: =IF('Group Z'!J15="","",'Group Z'!J15) | G30: =IF('Group Z'!J16="","",'Group Z'!J16) | H30: ='Group Z'!B26 -> 0/3 lecturers complete
A32: Panel progress | C32: Groups complete | D32: =COUNTIF(H5:H30,"Complete") -> 0 | E32: Groups remaining | F32: =COUNTA(A5:A30)-D32 -> 26 | G32: Phase 3 weight | H32: 50%
A34: HOW TO MARK
A35: 1. Open the relevant Group A–Z tab. Each lecturer enters their own name, seven criterion marks and feedback in their yellow cells. 2. Enter a numeric mark from zero up to the displayed maximum, including zero if applicable. 3. Presentation and live demonstration are one combined criterion worth 30 marks. 4. Design/prototype evidence subtotal /70, presentation /30, each lecturer's total /100, panel average /100 and the final weighted mark /50 calculate automatically. 5. The group is Complete only after all three lecturers enter all seven marks. Do not type marks into Panel Summary.

Sheet Group A
A1: ITC327W | PHASE 3: FINAL PROTOTYPE | GROUP A
A3: Group | B3: Group A | E3: Project / Stakeholder
A4: Assessment | B4: Assessment 3 (50% of module) | E4: Group Members
A7: Assessment criterion | B7: Maximum | C7: Excellent | D7: Good | E7: Satisfactory | F7: Inadequate | G7: Lecturer 1 | H7: Lecturer 2 | I7: Lecturer 3 | J7: Panel Average | K7: Panel Comment
A8: Shared Supabase Backend | B8: 15 | C8: Database implements the approved ERD, appropriate keys and relationships, and required operations. Authentication and access controls work where required. Both apps use one shared Supabase project. | D8: Required database structure and shared services are implemented with minor omissions or errors. | E8: Basic backend works, but important tables, operations, permissions or relationships are incomplete. | F8: Backend is largely incomplete, unreliable or not shared by the two applications. | J8: =IF(COUNT(G8:I8)=3,AVERAGE(G8:I8),"")
A9: Flutter Mobile Application | B9: 15 | C9: Approved main screens, navigation, forms and functions work reliably and use Supabase. Access and user workflows follow the SRS. | D9: Most approved screens and functions work; minor gaps do not substantially affect the intended workflows. | E9: Some mobile screens and functions work, but several important requirements or backend operations remain incomplete. | F9: Mobile application cannot demonstrate its main approved functions or is largely incomplete. | J9: =IF(COUNT(G9:I9)=3,AVERAGE(G9:I9),"")
A10: ASP.NET Web Application | B10: 15 | C10: Approved main pages, navigation, forms and functions work reliably and use Supabase. Access and user workflows follow the SRS. | D10: Most approved pages and functions work; minor gaps do not substantially affect the intended workflows. | E10: Some web pages and functions work, but several important requirements or backend operations remain incomplete. | F10: Web application cannot demonstrate its main approved functions or is largely incomplete. | J10: =IF(COUNT(G10:I10)=3,AVERAGE(G10:I10),"")
A11: Integration and Functional Correctness | B11: 15 | C11: Both applications use the same Supabase records. At least two important approved shared processes work end to end, with consistent retrieval, updates and permitted access. | D11: Shared backend and two relevant processes are demonstrated, with minor inconsistencies or limitations. | E11: Integration is partly functional; one or more shared processes, updates or access rules have important gaps. | F11: Applications do not meaningfully share data or required integrated processes cannot be demonstrated. | J11: =IF(COUNT(G11:I11)=3,AVERAGE(G11:I11),"")
A12: Final SRS and Implementation Evidence | B12: 5 | C12: The existing SRS is continued with a clear implementation section, requirement-to-function status, appropriate screenshots, approved changes, known limitations, GitHub link and MS Project screenshot. | D12: Updated SRS and evidence are mostly complete, with minor gaps. | E12: Implementation section or evidence is incomplete; requirements and working status are only partly documented. | F12: Final SRS or important implementation evidence is largely absent or inaccurate. | J12: =IF(COUNT(G12:I12)=3,AVERAGE(G12:I12),"")
A13: Microsoft Project, GitHub and Progress Tracker | B13: 5 | C13: Editable schedule reflects actual progress; GitHub and submitted ZIP contain the demonstrated version with organised code and setup guidance; tracker records tasks, contributions, challenges and final group reflection. | D13: Project records and source code are current and generally organised, with minor gaps. | E13: Some required files or updates are present, but progress, contributions, version consistency or setup details are weak. | F13: Essential project records or source code are missing, inaccessible or do not represent the demonstrated version. | J13: =IF(COUNT(G13:I13)=3,AVERAGE(G13:I13),"")
A14: Final Presentation and Live Demonstration | B14: 30 | C14: Clear, organised live demonstration of the working Flutter, ASP.NET and Supabase solution, including at least two shared processes. Members participate meaningfully, explain decisions and limitations, and answer panel questions accurately. | D14: Main functions and shared processes are demonstrated clearly; explanations, participation and responses have only minor gaps. | E14: Demonstration shows some functionality but has important gaps in integration, clarity, participation or defence. | F14: Live demonstration does not show the essential working system, or the group cannot adequately explain its work. | J14: =IF(COUNT(G14:I14)=3,AVERAGE(G14:I14),"")
A15: PROTOTYPE AND PROJECT EVIDENCE / 70 | G15: =IF(COUNT(G8:G13)=6,SUM(G8:G13),"") | H15: =IF(COUNT(H8:H13)=6,SUM(H8:H13),"") | I15: =IF(COUNT(I8:I13)=6,SUM(I8:I13),"") | J15: =IF(COUNT(G15:I15)=3,AVERAGE(G15:I15),"") | K15: Prototype subtotal /70
A16: FINAL PRESENTATION / 30 | G16: =IF(G14="","",G14) | H16: =IF(H14="","",H14) | I16: =IF(I14="","",I14) | J16: =IF(COUNT(G16:I16)=3,AVERAGE(G16:I16),"") | K16: Presentation subtotal /30
A17: LECTURER TOTALS / 100 | G17: =IF(COUNT(G8:G14)=7,SUM(G8:G14),"") | H17: =IF(COUNT(H8:H14)=7,SUM(H8:H14),"") | I17: =IF(COUNT(I8:I14)=7,SUM(I8:I14),"") | J17: =IF(COUNT(G17:I17)=3,AVERAGE(G17:I17),"") | K17: Panel average /100
A18: FINAL PHASE 3 MARK / 50 | J18: =IF(J17="","",J17*50/100) | K18: /50
A21: Lecturer 1 Feedback | D21: Lecturer 2 Feedback | G21: Lecturer 3 Feedback | J21: Panel / Final Feedback
A28: Marking Status | B28: =IF(COUNT(G17:I17)=3,"Complete",COUNT(G17:I17)&"/3 lecturers complete") -> 0/3 lecturers complete | J28: Panel Date

Sheet Group B
A1: ITC327W | PHASE 3: FINAL PROTOTYPE | GROUP B
A3: Group | B3: Group B | E3: Project / Stakeholder
A4: Assessment | B4: Assessment 3 (50% of module) | E4: Group Members
A7: Assessment criterion | B7: Maximum | C7: Excellent | D7: Good | E7: Satisfactory | F7: Inadequate | G7: Lecturer 1 | H7: Lecturer 2 | I7: Lecturer 3 | J7: Panel Average | K7: Panel Comment
A8: Shared Supabase Backend | B8: 15 | C8: Database implements the approved ERD, appropriate keys and relationships, and required operations. Authentication and access controls work where required. Both apps use one shared Supabase project. | D8: Required database structure and shared services are implemented with minor omissions or errors. | E8: Basic backend works, but important tables, operations, permissions or relationships are incomplete. | F8: Backend is largely incomplete, unreliable or not shared by the two applications. | J8: =IF(COUNT(G8:I8)=3,AVERAGE(G8:I8),"")
A9: Flutter Mobile Application | B9: 15 | C9: Approved main screens, navigation, forms and functions work reliably and use Supabase. Access and user workflows follow the SRS. | D9: Most approved screens and functions work; minor gaps do not substantially affect the intended workflows. | E9: Some mobile screens and functions work, but several important requirements or backend operations remain incomplete. | F9: Mobile application cannot demonstrate its main approved functions or is largely incomplete. | J9: =IF(COUNT(G9:I9)=3,AVERAGE(G9:I9),"")
A10: ASP.NET Web Application | B10: 15 | C10: Approved main pages, navigation, forms and functions work reliably and use Supabase. Access and user workflows follow the SRS. | D10: Most approved pages and functions work; minor gaps do not substantially affect the intended workflows. | E10: Some web pages and functions work, but several important requirements or backend operations remain incomplete. | F10: Web application cannot demonstrate its main approved functions or is largely incomplete. | J10: =IF(COUNT(G10:I10)=3,AVERAGE(G10:I10),"")
A11: Integration and Functional Correctness | B11: 15 | C11: Both applications use the same Supabase records. At least two important approved shared processes work end to end, with consistent retrieval, updates and permitted access. | D11: Shared backend and two relevant processes are demonstrated, with minor inconsistencies or limitations. | E11: Integration is partly functional; one or more shared processes, updates or access rules have important gaps. | F11: Applications do not meaningfully share data or required integrated processes cannot be demonstrated. | J11: =IF(COUNT(G11:I11)=3,AVERAGE(G11:I11),"")
A12: Final SRS and Implementation Evidence | B12: 5 | C12: The existing SRS is continued with a clear implementation section, requirement-to-function status, appropriate screenshots, approved changes, known limitations, GitHub link and MS Project screenshot. | D12: Updated SRS and evidence are mostly complete, with minor gaps. | E12: Implementation section or evidence is incomplete; requirements and working status are only partly documented. | F12: Final SRS or important implementation evidence is largely absent or inaccurate. | J12: =IF(COUNT(G12:I12)=3,AVERAGE(G12:I12),"")
A13: Microsoft Project, GitHub and Progress Tracker | B13: 5 | C13: Editable schedule reflects actual progress; GitHub and submitted ZIP contain the demonstrated version with organised code and setup guidance; tracker records tasks, contributions, challenges and final group reflection. | D13: Project records and source code are current and generally organised, with minor gaps. | E13: Some required files or updates are present, but progress, contributions, version consistency or setup details are weak. | F13: Essential project records or source code are missing, inaccessible or do not represent the demonstrated version. | J13: =IF(COUNT(G13:I13)=3,AVERAGE(G13:I13),"")
A14: Final Presentation and Live Demonstration | B14: 30 | C14: Clear, organised live demonstration of the working Flutter, ASP.NET and Supabase solution, including at least two shared processes. Members participate meaningfully, explain decisions and limitations, and answer panel questions accurately. | D14: Main functions and shared processes are demonstrated clearly; explanations, participation and responses have only minor gaps. | E14: Demonstration shows some functionality but has important gaps in integration, clarity, participation or defence. | F14: Live demonstration does not show the essential working system, or the group cannot adequately explain its work. | J14: =IF(COUNT(G14:I14)=3,AVERAGE(G14:I14),"")
A15: PROTOTYPE AND PROJECT EVIDENCE / 70 | G15: =IF(COUNT(G8:G13)=6,SUM(G8:G13),"") | H15: =IF(COUNT(H8:H13)=6,SUM(H8:H13),"") | I15: =IF(COUNT(I8:I13)=6,SUM(I8:I13),"") | J15: =IF(COUNT(G15:I15)=3,AVERAGE(G15:I15),"") | K15: Prototype subtotal /70
A16: FINAL PRESENTATION / 30 | G16: =IF(G14="","",G14) | H16: =IF(H14="","",H14) | I16: =IF(I14="","",I14) | J16: =IF(COUNT(G16:I16)=3,AVERAGE(G16:I16),"") | K16: Presentation subtotal /30
A17: LECTURER TOTALS / 100 | G17: =IF(COUNT(G8:G14)=7,SUM(G8:G14),"") | H17: =IF(COUNT(H8:H14)=7,SUM(H8:H14),"") | I17: =IF(COUNT(I8:I14)=7,SUM(I8:I14),"") | J17: =IF(COUNT(G17:I17)=3,AVERAGE(G17:I17),"") | K17: Panel average /100
A18: FINAL PHASE 3 MARK / 50 | J18: =IF(J17="","",J17*50/100) | K18: /50
A21: Lecturer 1 Feedback | D21: Lecturer 2 Feedback | G21: Lecturer 3 Feedback | J21: Panel / Final Feedback
A28: Marking Status | B28: =IF(COUNT(G17:I17)=3,"Complete",COUNT(G17:I17)&"/3 lecturers complete") -> 0/3 lecturers complete | J28: Panel Date

Sheet Group C
A1: ITC327W | PHASE 3: FINAL PROTOTYPE | GROUP C
A3: Group | B3: Group C | E3: Project / Stakeholder
A4: Assessment | B4: Assessment 3 (50% of module) | E4: Group Members
A7: Assessment criterion | B7: Maximum | C7: Excellent | D7: Good | E7: Satisfactory | F7: Inadequate | G7: Lecturer 1 | H7: Lecturer 2 | I7: Lecturer 3 | J7: Panel Average | K7: Panel Comment
A8: Shared Supabase Backend | B8: 15 | C8: Database implements the approved ERD, appropriate keys and relationships, and required operations. Authentication and access controls work where required. Both apps use one shared Supabase project. | D8: Required database structure and shared services are implemented with minor omissions or errors. | E8: Basic backend works, but important tables, operations, permissions or relationships are incomplete. | F8: Backend is largely incomplete, unreliable or not shared by the two applications. | J8: =IF(COUNT(G8:I8)=3,AVERAGE(G8:I8),"")
A9: Flutter Mobile Application | B9: 15 | C9: Approved main screens, navigation, forms and functions work reliably and use Supabase. Access and user workflows follow the SRS. | D9: Most approved screens and functions work; minor gaps do not substantially affect the intended workflows. | E9: Some mobile screens and functions work, but several important requirements or backend operations remain incomplete. | F9: Mobile application cannot demonstrate its main approved functions or is largely incomplete. | J9: =IF(COUNT(G9:I9)=3,AVERAGE(G9:I9),"")
A10: ASP.NET Web Application | B10: 15 | C10: Approved main pages, navigation, forms and functions work reliably and use Supabase. Access and user workflows follow the SRS. | D10: Most approved pages and functions work; minor gaps do not substantially affect the intended workflows. | E10: Some web pages and functions work, but several important requirements or backend operations remain incomplete. | F10: Web application cannot demonstrate its main approved functions or is largely incomplete. | J10: =IF(COUNT(G10:I10)=3,AVERAGE(G10:I10),"")
A11: Integration and Functional Correctness | B11: 15 | C11: Both applications use the same Supabase records. At least two important approved shared processes work end to end, with consistent retrieval, updates and permitted access. | D11: Shared backend and two relevant processes are demonstrated, with minor inconsistencies or limitations. | E11: Integration is partly functional; one or more shared processes, updates or access rules have important gaps. | F11: Applications do not meaningfully share data or required integrated processes cannot be demonstrated. | J11: =IF(COUNT(G11:I11)=3,AVERAGE(G11:I11),"")
A12: Final SRS and Implementation Evidence | B12: 5 | C12: The existing SRS is continued with a clear implementation section, requirement-to-function status, appropriate screenshots, approved changes, known limitations, GitHub link and MS Project screenshot. | D12: Updated SRS and evidence are mostly complete, with minor gaps. | E12: Implementation section or evidence is incomplete; requirements and working status are only partly documented. | F12: Final SRS or important implementation evidence is largely absent or inaccurate. | J12: =IF(COUNT(G12:I12)=3,AVERAGE(G12:I12),"")
A13: Microsoft Project, GitHub and Progress Tracker | B13: 5 | C13: Editable schedule reflects actual progress; GitHub and submitted ZIP contain the demonstrated version with organised code and setup guidance; tracker records tasks, contributions, challenges and final group reflection. | D13: Project records and source code are current and generally organised, with minor gaps. | E13: Some required files or updates are present, but progress, contributions, version consistency or setup details are weak. | F13: Essential project records or source code are missing, inaccessible or do not represent the demonstrated version. | J13: =IF(COUNT(G13:I13)=3,AVERAGE(G13:I13),"")
A14: Final Presentation and Live Demonstration | B14: 30 | C14: Clear, organised live demonstration of the working Flutter, ASP.NET and Supabase solution, including at least two shared processes. Members participate meaningfully, explain decisions and limitations, and answer panel questions accurately. | D14: Main functions and shared processes are demonstrated clearly; explanations, participation and responses have only minor gaps. | E14: Demonstration shows some functionality but has important gaps in integration, clarity, participation or defence. | F14: Live demonstration does not show the essential working system, or the group cannot adequately explain its work. | J14: =IF(COUNT(G14:I14)=3,AVERAGE(G14:I14),"")
A15: PROTOTYPE AND PROJECT EVIDENCE / 70 | G15: =IF(COUNT(G8:G13)=6,SUM(G8:G13),"") | H15: =IF(COUNT(H8:H13)=6,SUM(H8:H13),"") | I15: =IF(COUNT(I8:I13)=6,SUM(I8:I13),"") | J15: =IF(COUNT(G15:I15)=3,AVERAGE(G15:I15),"") | K15: Prototype subtotal /70
A16: FINAL PRESENTATION / 30 | G16: =IF(G14="","",G14) | H16: =IF(H14="","",H14) | I16: =IF(I14="","",I14) | J16: =IF(COUNT(G16:I16)=3,AVERAGE(G16:I16),"") | K16: Presentation subtotal /30
A17: LECTURER TOTALS / 100 | G17: =IF(COUNT(G8:G14)=7,SUM(G8:G14),"") | H17: =IF(COUNT(H8:H14)=7,SUM(H8:H14),"") | I17: =IF(COUNT(I8:I14)=7,SUM(I8:I14),"") | J17: =IF(COUNT(G17:I17)=3,AVERAGE(G17:I17),"") | K17: Panel average /100
A18: FINAL PHASE 3 MARK / 50 | J18: =IF(J17="","",J17*50/100) | K18: /50
A21: Lecturer 1 Feedback | D21: Lecturer 2 Feedback | G21: Lecturer 3 Feedback | J21: Panel / Final Feedback
A28: Marking Status | B28: =IF(COUNT(G17:I17)=3,"Complete",COUNT(G17:I17)&"/3 lecturers complete") -> 0/3 lecturers complete | J28: Panel Date

Sheet Group D
A3: Group | B3: Group D | E3: Project / Stakeholder
A4: Assessment | B4: Assessment 3 (50% of module) | E4: Group Members
A7: Assessment criterion | B7: Maximum | C7: Excellent | D7: Good | E7: Satisfactory | F7: Inadequate | G7: Lecturer 1 | H7: Lecturer 2 | I7: Lecturer 3 | J7: Panel Average | K7: Panel Comment
A8: Shared Supabase Backend | B8: 15 | C8: Database implements the approved ERD, appropriate keys and relationships, and required operations. Authentication and access controls work where required. Both apps use one shared Supabase project. | D8: Required database structure and shared services are implemented with minor omissions or errors. | E8: Basic backend works, but important tables, operations, permissions or relationships are incomplete. | F8: Backend is largely incomplete, unreliable or not shared by the two applications. | J8: =IF(COUNT(G8:I8)=3,AVERAGE(G8:I8),"")
A9: Flutter Mobile Application | B9: 15 | C9: Approved main screens, navigation, forms and functions work reliably and use Supabase. Access and user workflows follow the SRS. | D9: Most approved screens and functions work; minor gaps do not substantially affect the intended workflows. | E9: Some mobile screens and functions work, but several important requirements or backend operations remain incomplete. | F9: Mobile application cannot demonstrate its main approved functions or is largely incomplete. | J9: =IF(COUNT(G9:I9)=3,AVERAGE(G9:I9),"")
A10: ASP.NET Web Application | B10: 15 | C10: Approved main pages, navigation, forms and functions work reliably and use Supabase. Access and user workflows follow the SRS. | D10: Most approved pages and functions work; minor gaps do not substantially affect the intended workflows. | E10: Some web pages and functions work, but several important requirements or backend operations remain incomplete. | F10: Web application cannot demonstrate its main approved functions or is largely incomplete. | J10: =IF(COUNT(G10:I10)=3,AVERAGE(G10:I10),"")
A11: Integration and Functional Correctness | B11: 15 | C11: Both applications use the same Supabase records. At least two important approved shared processes work end to end, with consistent retrieval, updates and permitted access. | D11: Shared backend and two relevant processes are demonstrated, with minor inconsistencies or limitations. | E11: Integration is partly functional; one or more shared processes, updates or access rules have important gaps. | F11: Applications do not meaningfully share data or required integrated processes cannot be demonstrated. | J11: =IF(COUNT(G11:I11)=3,AVERAGE(G11:I11),"")
A12: Final SRS and Implementation Evidence | B12: 5 | C12: The existing SRS is continued with a clear implementation section, requirement-to-function status, appropriate screenshots, approved changes, known limitations, GitHub link and MS Project screenshot. | D12: Updated SRS and evidence are mostly complete, with minor gaps. | E12: Implementation section or evidence is incomplete; requirements and working status are only partly documented. | F12: Final SRS or important implementation evidence is largely absent or inaccurate. | J12: =IF(COUNT(G12:I12)=3,AVERAGE(G12:I12),"")
A13: Microsoft Project, GitHub and Progress Tracker | B13: 5 | C13: Editable schedule reflects actual progress; GitHub and submitted ZIP contain the demonstrated version with organised code and setup guidance; tracker records tasks, contributions, challenges and final group reflection. | D13: Project records and source code are current and generally organised, with minor gaps. | E13: Some required files or updates are present, but progress, contributions, version consistency or setup details are weak. | F13: Essential project records or source code are missing, inaccessible or do not represent the demonstrated version. | J13: =IF(COUNT(G13:I13)=3,AVERAGE(G13:I13),"")
A14: Final Presentation and Live Demonstration | B14: 30 | C14: Clear, organised live demonstration of the working Flutter, ASP.NET and Supabase solution, including at least two shared processes. Members participate meaningfully, explain decisions and limitations, and answer panel questions accurately. | D14: Main functions and shared processes are demonstrated clearly; explanations, participation and responses have only minor gaps. | E14: Demonstration shows some functionality but has important gaps in integration, clarity, participation or defence. | F14: Live demonstration does not show the essential working system, or the group cannot adequately explain its work. | J14: =IF(COUNT(G14:I14)=3,AVERAGE(G14:I14),"")
A15: PROTOTYPE AND PROJECT EVIDENCE / 70 | G15: =IF(COUNT(G8:G13)=6,SUM(G8:G13),"") | H15: =IF(COUNT(H8:H13)=6,SUM(H8:H13),"") | I15: =IF(COUNT(I8:I13)=6,SUM(I8:I13),"") | J15: =IF(COUNT(G15:I15)=3,AVERAGE(G15:I15),"") | K15: Prototype subtotal /70
A16: FINAL PRESENTATION / 30 | G16: =IF(G14="","",G14) | H16: =IF(H14="","",H14) | I16: =IF(I14="","",I14) | J16: =IF(COUNT(G16:I16)=3,AVERAGE(G16:I16),"") | K16: Presentation subtotal /30
A17: LECTURER TOTALS / 100 | G17: =IF(COUNT(G8:G14)=7,SUM(G8:G14),"") | H17: =IF(COUNT(H8:H14)=7,SUM(H8:H14),"") | I17: =IF(COUNT(I8:I14)=7,SUM(I8:I14),"") | J17: =IF(COUNT(G17:I17)=3,AVERAGE(G17:I17),"") | K17: Panel average /100
A18: FINAL PHASE 3 MARK / 50 | J18: =IF(J17="","",J17*50/100) | K18: /50
A21: Lecturer 1 Feedback | D21: Lecturer 2 Feedback | G21: Lecturer 3 Feedback | J21: Panel / Final Feedback
A28: Marking Status | B28: =IF(COUNT(G17:I17)=3,"Complete",COUNT(G17:I17)&"/3 lecturers complete") -> 0/3 lecturers complete | J28: Panel Date

Sheet Group E
A1: ITC327W | PHASE 3: FINAL PROTOTYPE | GROUP E
A3: Group | B3: Group E | E3: Project / Stakeholder
A4: Assessment | B4: Assessment 3 (50% of module) | E4: Group Members
A7: Assessment criterion | B7: Maximum | C7: Excellent | D7: Good | E7: Satisfactory | F7: Inadequate | G7: Lecturer 1 | H7: Lecturer 2 | I7: Lecturer 3 | J7: Panel Average | K7: Panel Comment
A8: Shared Supabase Backend | B8: 15 | C8: Database implements the approved ERD, appropriate keys and relationships, and required operations. Authentication and access controls work where required. Both apps use one shared Supabase project. | D8: Required database structure and shared services are implemented with minor omissions or errors. | E8: Basic backend works, but important tables, operations, permissions or relationships are incomplete. | F8: Backend is largely incomplete, unreliable or not shared by the two applications. | J8: =IF(COUNT(G8:I8)=3,AVERAGE(G8:I8),"")
A9: Flutter Mobile Application | B9: 15 | C9: Approved main screens, navigation, forms and functions work reliably and use Supabase. Access and user workflows follow the SRS. | D9: Most approved screens and functions work; minor gaps do not substantially affect the intended workflows. | E9: Some mobile screens and functions work, but several important requirements or backend operations remain incomplete. | F9: Mobile application cannot demonstrate its main approved functions or is largely incomplete. | J9: =IF(COUNT(G9:I9)=3,AVERAGE(G9:I9),"")
A10: ASP.NET Web Application | B10: 15 | C10: Approved main pages, navigation, forms and functions work reliably and use Supabase. Access and user workflows follow the SRS. | D10: Most approved pages and functions work; minor gaps do not substantially affect the intended workflows. | E10: Some web pages and functions work, but several important requirements or backend operations remain incomplete. | F10: Web application cannot demonstrate its main approved functions or is largely incomplete. | J10: =IF(COUNT(G10:I10)=3,AVERAGE(G10:I10),"")
A11: Integration and Functional Correctness | B11: 15 | C11: Both applications use the same Supabase records. At least two important approved shared processes work end to end, with consistent retrieval, updates and permitted access. | D11: Shared backend and two relevant processes are demonstrated, with minor inconsistencies or limitations. | E11: Integration is partly functional; one or more shared processes, updates or access rules have important gaps. | F11: Applications do not meaningfully share data or required integrated processes cannot be demonstrated. | J11: =IF(COUNT(G11:I11)=3,AVERAGE(G11:I11),"")
A12: Final SRS and Implementation Evidence | B12: 5 | C12: The existing SRS is continued with a clear implementation section, requirement-to-function status, appropriate screenshots, approved changes, known limitations, GitHub link and MS Project screenshot. | D12: Updated SRS and evidence are mostly complete, with minor gaps. | E12: Implementation section or evidence is incomplete; requirements and working status are only partly documented. | F12: Final SRS or important implementation evidence is largely absent or inaccurate. | J12: =IF(COUNT(G12:I12)=3,AVERAGE(G12:I12),"")
A13: Microsoft Project, GitHub and Progress Tracker | B13: 5 | C13: Editable schedule reflects actual progress; GitHub and submitted ZIP contain the demonstrated version with organised code and setup guidance; tracker records tasks, contributions, challenges and final group reflection. | D13: Project records and source code are current and generally organised, with minor gaps. | E13: Some required files or updates are present, but progress, contributions, version consistency or setup details are weak. | F13: Essential project records or source code are missing, inaccessible or do not represent the demonstrated version. | J13: =IF(COUNT(G13:I13)=3,AVERAGE(G13:I13),"")
A14: Final Presentation and Live Demonstration | B14: 30 | C14: Clear, organised live demonstration of the working Flutter, ASP.NET and Supabase solution, including at least two shared processes. Members participate meaningfully, explain decisions and limitations, and answer panel questions accurately. | D14: Main functions and shared processes are demonstrated clearly; explanations, participation and responses have only minor gaps. | E14: Demonstration shows some functionality but has important gaps in integration, clarity, participation or defence. | F14: Live demonstration does not show the essential working system, or the group cannot adequately explain its work. | J14: =IF(COUNT(G14:I14)=3,AVERAGE(G14:I14),"")
A15: PROTOTYPE AND PROJECT EVIDENCE / 70 | G15: =IF(COUNT(G8:G13)=6,SUM(G8:G13),"") | H15: =IF(COUNT(H8:H13)=6,SUM(H8:H13),"") | I15: =IF(COUNT(I8:I13)=6,SUM(I8:I13),"") | J15: =IF(COUNT(G15:I15)=3,AVERAGE(G15:I15),"") | K15: Prototype subtotal /70
A16: FINAL PRESENTATION / 30 | G16: =IF(G14="","",G14) | H16: =IF(H14="","",H14) | I16: =IF(I14="","",I14) | J16: =IF(COUNT(G16:I16)=3,AVERAGE(G16:I16),"") | K16: Presentation subtotal /30
A17: LECTURER TOTALS / 100 | G17: =IF(COUNT(G8:G14)=7,SUM(G8:G14),"") | H17: =IF(COUNT(H8:H14)=7,SUM(H8:H14),"") | I17: =IF(COUNT(I8:I14)=7,SUM(I8:I14),"") | J17: =IF(COUNT(G17:I17)=3,AVERAGE(G17:I17),"") | K17: Panel average /100
A18: FINAL PHASE 3 MARK / 50 | J18: =IF(J17="","",J17*50/100) | K18: /50
A21: Lecturer 1 Feedback | D21: Lecturer 2 Feedback | G21: Lecturer 3 Feedback | J21: Panel / Final Feedback
A28: Marking Status | B28: =IF(COUNT(G17:I17)=3,"Complete",COUNT(G17:I17)&"/3 lecturers complete") -> 0/3 lecturers complete | J28: Panel Date

Sheet Group F
A1: ITC327W | PHASE 3: FINAL PROTOTYPE | GROUP F
A3: Group | B3: Group F | E3: Project / Stakeholder
A4: Assessment | B4: Assessment 3 (50% of module) | E4: Group Members
A7: Assessment criterion | B7: Maximum | C7: Excellent | D7: Good | E7: Satisfactory | F7: Inadequate | G7: Lecturer 1 | H7: Lecturer 2 | I7: Lecturer 3 | J7: Panel Average | K7: Panel Comment
A8: Shared Supabase Backend | B8: 15 | C8: Database implements the approved ERD, appropriate keys and relationships, and required operations. Authentication and access controls work where required. Both apps use one shared Supabase project. | D8: Required database structure and shared services are implemented with minor omissions or errors. | E8: Basic backend works, but important tables, operations, permissions or relationships are incomplete. | F8: Backend is largely incomplete, unreliable or not shared by the two applications. | J8: =IF(COUNT(G8:I8)=3,AVERAGE(G8:I8),"")
A9: Flutter Mobile Application | B9: 15 | C9: Approved main screens, navigation, forms and functions work reliably and use Supabase. Access and user workflows follow the SRS. | D9: Most approved screens and functions work; minor gaps do not substantially affect the intended workflows. | E9: Some mobile screens and functions work, but several important requirements or backend operations remain incomplete. | F9: Mobile application cannot demonstrate its main approved functions or is largely incomplete. | J9: =IF(COUNT(G9:I9)=3,AVERAGE(G9:I9),"")
A10: ASP.NET Web Application | B10: 15 | C10: Approved main pages, navigation, forms and functions work reliably and use Supabase. Access and user workflows follow the SRS. | D10: Most approved pages and functions work; minor gaps do not substantially affect the intended workflows. | E10: Some web pages and functions work, but several important requirements or backend operations remain incomplete. | F10: Web application cannot demonstrate its main approved functions or is largely incomplete. | J10: =IF(COUNT(G10:I10)=3,AVERAGE(G10:I10),"")
A11: Integration and Functional Correctness | B11: 15 | C11: Both applications use the same Supabase records. At least two important approved shared processes work end to end, with consistent retrieval, updates and permitted access. | D11: Shared backend and two relevant processes are demonstrated, with minor inconsistencies or limitations. | E11: Integration is partly functional; one or more shared processes, updates or access rules have important gaps. | F11: Applications do not meaningfully share data or required integrated processes cannot be demonstrated. | J11: =IF(COUNT(G11:I11)=3,AVERAGE(G11:I11),"")
A12: Final SRS and Implementation Evidence | B12: 5 | C12: The existing SRS is continued with a clear implementation section, requirement-to-function status, appropriate screenshots, approved changes, known limitations, GitHub link and MS Project screenshot. | D12: Updated SRS and evidence are mostly complete, with minor gaps. | E12: Implementation section or evidence is incomplete; requirements and working status are only partly documented. | F12: Final SRS or important implementation evidence is largely absent or inaccurate. | J12: =IF(COUNT(G12:I12)=3,AVERAGE(G12:I12),"")
A13: Microsoft Project, GitHub and Progress Tracker | B13: 5 | C13: Editable schedule reflects actual progress; GitHub and submitted ZIP contain the demonstrated version with organised code and setup guidance; tracker records tasks, contributions, challenges and final group reflection. | D13: Project records and source code are current and generally organised, with minor gaps. | E13: Some required files or updates are present, but progress, contributions, version consistency or setup details are weak. | F13: Essential project records or source code are missing, inaccessible or do not represent the demonstrated version. | J13: =IF(COUNT(G13:I13)=3,AVERAGE(G13:I13),"")
A14: Final Presentation and Live Demonstration | B14: 30 | C14: Clear, organised live demonstration of the working Flutter, ASP.NET and Supabase solution, including at least two shared processes. Members participate meaningfully, explain decisions and limitations, and answer panel questions accurately. | D14: Main functions and shared processes are demonstrated clearly; explanations, participation and responses have only minor gaps. | E14: Demonstration shows some functionality but has important gaps in integration, clarity, participation or defence. | F14: Live demonstration does not show the essential working system, or the group cannot adequately explain its work. | J14: =IF(COUNT(G14:I14)=3,AVERAGE(G14:I14),"")
A15: PROTOTYPE AND PROJECT EVIDENCE / 70 | G15: =IF(COUNT(G8:G13)=6,SUM(G8:G13),"") | H15: =IF(COUNT(H8:H13)=6,SUM(H8:H13),"") | I15: =IF(COUNT(I8:I13)=6,SUM(I8:I13),"") | J15: =IF(COUNT(G15:I15)=3,AVERAGE(G15:I15),"") | K15: Prototype subtotal /70
A16: FINAL PRESENTATION / 30 | G16: =IF(G14="","",G14) | H16: =IF(H14="","",H14) | I16: =IF(I14="","",I14) | J16: =IF(COUNT(G16:I16)=3,AVERAGE(G16:I16),"") | K16: Presentation subtotal /30
A17: LECTURER TOTALS / 100 | G17: =IF(COUNT(G8:G14)=7,SUM(G8:G14),"") | H17: =IF(COUNT(H8:H14)=7,SUM(H8:H14),"") | I17: =IF(COUNT(I8:I14)=7,SUM(I8:I14),"") | J17: =IF(COUNT(G17:I17)=3,AVERAGE(G17:I17),"") | K17: Panel average /100
A18: FINAL PHASE 3 MARK / 50 | J18: =IF(J17="","",J17*50/100) | K18: /50
A21: Lecturer 1 Feedback | D21: Lecturer 2 Feedback | G21: Lecturer 3 Feedback | J21: Panel / Final Feedback
A28: Marking Status | B28: =IF(COUNT(G17:I17)=3,"Complete",COUNT(G17:I17)&"/3 lecturers complete") -> 0/3 lecturers complete | J28: Panel Date

Sheet Group G
A1: ITC327W | PHASE 3: FINAL PROTOTYPE | GROUP G
A3: Group | B3: Group G | E3: Project / Stakeholder
A4: Assessment | B4: Assessment 3 (50% of module) | E4: Group Members
A7: Assessment criterion | B7: Maximum | C7: Excellent | D7: Good | E7: Satisfactory | F7: Inadequate | G7: Lecturer 1 | H7: Lecturer 2 | I7: Lecturer 3 | J7: Panel Average | K7: Panel Comment
A8: Shared Supabase Backend | B8: 15 | C8: Database implements the approved ERD, appropriate keys and relationships, and required operations. Authentication and access controls work where required. Both apps use one shared Supabase project. | D8: Required database structure and shared services are implemented with minor omissions or errors. | E8: Basic backend works, but important tables, operations, permissions or relationships are incomplete. | F8: Backend is largely incomplete, unreliable or not shared by the two applications. | J8: =IF(COUNT(G8:I8)=3,AVERAGE(G8:I8),"")
A9: Flutter Mobile Application | B9: 15 | C9: Approved main screens, navigation, forms and functions work reliably and use Supabase. Access and user workflows follow the SRS. | D9: Most approved screens and functions work; minor gaps do not substantially affect the intended workflows. | E9: Some mobile screens and functions work, but several important requirements or backend operations remain incomplete. | F9: Mobile application cannot demonstrate its main approved functions or is largely incomplete. | J9: =IF(COUNT(G9:I9)=3,AVERAGE(G9:I9),"")
A10: ASP.NET Web Application | B10: 15 | C10: Approved main pages, navigation, forms and functions work reliably and use Supabase. Access and user workflows follow the SRS. | D10: Most approved pages and functions work; minor gaps do not substantially affect the intended workflows. | E10: Some web pages and functions work, but several important requirements or backend operations remain incomplete. | F10: Web application cannot demonstrate its main approved functions or is largely incomplete. | J10: =IF(COUNT(G10:I10)=3,AVERAGE(G10:I10),"")
A11: Integration and Functional Correctness | B11: 15 | C11: Both applications use the same Supabase records. At least two important approved shared processes work end to end, with consistent retrieval, updates and permitted access. | D11: Shared backend and two relevant processes are demonstrated, with minor inconsistencies or limitations. | E11: Integration is partly functional; one or more shared processes, updates or access rules have important gaps. | F11: Applications do not meaningfully share data or required integrated processes cannot be demonstrated. | J11: =IF(COUNT(G11:I11)=3,AVERAGE(G11:I11),"")
A12: Final SRS and Implementation Evidence | B12: 5 | C12: The existing SRS is continued with a clear implementation section, requirement-to-function status, appropriate screenshots, approved changes, known limitations, GitHub link and MS Project screenshot. | D12: Updated SRS and evidence are mostly complete, with minor gaps. | E12: Implementation section or evidence is incomplete; requirements and working status are only partly documented. | F12: Final SRS or important implementation evidence is largely absent or inaccurate. | J12: =IF(COUNT(G12:I12)=3,AVERAGE(G12:I12),"")
A13: Microsoft Project, GitHub and Progress Tracker | B13: 5 | C13: Editable schedule reflects actual progress; GitHub and submitted ZIP contain the demonstrated version with organised code and setup guidance; tracker records tasks, contributions, challenges and final group reflection. | D13: Project records and source code are current and generally organised, with minor gaps. | E13: Some required files or updates are present, but progress, contributions, version consistency or setup details are weak. | F13: Essential project records or source code are missing, inaccessible or do not represent the demonstrated version. | J13: =IF(COUNT(G13:I13)=3,AVERAGE(G13:I13),"")
A14: Final Presentation and Live Demonstration | B14: 30 | C14: Clear, organised live demonstration of the working Flutter, ASP.NET and Supabase solution, including at least two shared processes. Members participate meaningfully, explain decisions and limitations, and answer panel questions accurately. | D14: Main functions and shared processes are demonstrated clearly; explanations, participation and responses have only minor gaps. | E14: Demonstration shows some functionality but has important gaps in integration, clarity, participation or defence. | F14: Live demonstration does not show the essential working system, or the group cannot adequately explain its work. | J14: =IF(COUNT(G14:I14)=3,AVERAGE(G14:I14),"")
A15: PROTOTYPE AND PROJECT EVIDENCE / 70 | G15: =IF(COUNT(G8:G13)=6,SUM(G8:G13),"") | H15: =IF(COUNT(H8:H13)=6,SUM(H8:H13),"") | I15: =IF(COUNT(I8:I13)=6,SUM(I8:I13),"") | J15: =IF(COUNT(G15:I15)=3,AVERAGE(G15:I15),"") | K15: Prototype subtotal /70
A16: FINAL PRESENTATION / 30 | G16: =IF(G14="","",G14) | H16: =IF(H14="","",H14) | I16: =IF(I14="","",I14) | J16: =IF(COUNT(G16:I16)=3,AVERAGE(G16:I16),"") | K16: Presentation subtotal /30
A17: LECTURER TOTALS / 100 | G17: =IF(COUNT(G8:G14)=7,SUM(G8:G14),"") | H17: =IF(COUNT(H8:H14)=7,SUM(H8:H14),"") | I17: =IF(COUNT(I8:I14)=7,SUM(I8:I14),"") | J17: =IF(COUNT(G17:I17)=3,AVERAGE(G17:I17),"") | K17: Panel average /100
A18: FINAL PHASE 3 MARK / 50 | J18: =IF(J17="","",J17*50/100) | K18: /50
A21: Lecturer 1 Feedback | D21: Lecturer 2 Feedback | G21: Lecturer 3 Feedback | J21: Panel / Final Feedback
A28: Marking Status | B28: =IF(COUNT(G17:I17)=3,"Complete",COUNT(G17:I17)&"/3 lecturers complete") -> 0/3 lecturers complete | J28: Panel Date

Sheet Group H
A1: ITC327W | PHASE 3: FINAL PROTOTYPE | GROUP H
A3: Group | B3: Group H | E3: Project / Stakeholder
A4: Assessment | B4: Assessment 3 (50% of module) | E4: Group Members
A7: Assessment criterion | B7: Maximum | C7: Excellent | D7: Good | E7: Satisfactory | F7: Inadequate | G7: Lecturer 1 | H7: Lecturer 2 | I7: Lecturer 3 | J7: Panel Average | K7: Panel Comment
A8: Shared Supabase Backend | B8: 15 | C8: Database implements the approved ERD, appropriate keys and relationships, and required operations. Authentication and access controls work where required. Both apps use one shared Supabase project. | D8: Required database structure and shared services are implemented with minor omissions or errors. | E8: Basic backend works, but important tables, operations, permissions or relationships are incomplete. | F8: Backend is largely incomplete, unreliable or not shared by the two applications. | J8: =IF(COUNT(G8:I8)=3,AVERAGE(G8:I8),"")
A9: Flutter Mobile Application | B9: 15 | C9: Approved main screens, navigation, forms and functions work reliably and use Supabase. Access and user workflows follow the SRS. | D9: Most approved screens and functions work; minor gaps do not substantially affect the intended workflows. | E9: Some mobile screens and functions work, but several important requirements or backend operations remain incomplete. | F9: Mobile application cannot demonstrate its main approved functions or is largely incomplete. | J9: =IF(COUNT(G9:I9)=3,AVERAGE(G9:I9),"")
A10: ASP.NET Web Application | B10: 15 | C10: Approved main pages, navigation, forms and functions work reliably and use Supabase. Access and user workflows follow the SRS. | D10: Most approved pages and functions work; minor gaps do not substantially affect the intended workflows. | E10: Some web pages and functions work, but several important requirements or backend operations remain incomplete. | F10: Web application cannot demonstrate its main approved functions or is largely incomplete. | J10: =IF(COUNT(G10:I10)=3,AVERAGE(G10:I10),"")
A11: Integration and Functional Correctness | B11: 15 | C11: Both applications use the same Supabase records. At least two important approved shared processes work end to end, with consistent retrieval, updates and permitted access. | D11: Shared backend and two relevant processes are demonstrated, with minor inconsistencies or limitations. | E11: Integration is partly functional; one or more shared processes, updates or access rules have important gaps. | F11: Applications do not meaningfully share data or required integrated processes cannot be demonstrated. | J11: =IF(COUNT(G11:I11)=3,AVERAGE(G11:I11),"")
A12: Final SRS and Implementation Evidence | B12: 5 | C12: The existing SRS is continued with a clear implementation section, requirement-to-function status, appropriate screenshots, approved changes, known limitations, GitHub link and MS Project screenshot. | D12: Updated SRS and evidence are mostly complete, with minor gaps. | E12: Implementation section or evidence is incomplete; requirements and working status are only partly documented. | F12: Final SRS or important implementation evidence is largely absent or inaccurate. | J12: =IF(COUNT(G12:I12)=3,AVERAGE(G12:I12),"")
A13: Microsoft Project, GitHub and Progress Tracker | B13: 5 | C13: Editable schedule reflects actual progress; GitHub and submitted ZIP contain the demonstrated version with organised code and setup guidance; tracker records tasks, contributions, challenges and final group reflection. | D13: Project records and source code are current and generally organised, with minor gaps. | E13: Some required files or updates are present, but progress, contributions, version consistency or setup details are weak. | F13: Essential project records or source code are missing, inaccessible or do not represent the demonstrated version. | J13: =IF(COUNT(G13:I13)=3,AVERAGE(G13:I13),"")
A14: Final Presentation and Live Demonstration | B14: 30 | C14: Clear, organised live demonstration of the working Flutter, ASP.NET and Supabase solution, including at least two shared processes. Members participate meaningfully, explain decisions and limitations, and answer panel questions accurately. | D14: Main functions and shared processes are demonstrated clearly; explanations, participation and responses have only minor gaps. | E14: Demonstration shows some functionality but has important gaps in integration, clarity, participation or defence. | F14: Live demonstration does not show the essential working system, or the group cannot adequately explain its work. | J14: =IF(COUNT(G14:I14)=3,AVERAGE(G14:I14),"")
A15: PROTOTYPE AND PROJECT EVIDENCE / 70 | G15: =IF(COUNT(G8:G13)=6,SUM(G8:G13),"") | H15: =IF(COUNT(H8:H13)=6,SUM(H8:H13),"") | I15: =IF(COUNT(I8:I13)=6,SUM(I8:I13),"") | J15: =IF(COUNT(G15:I15)=3,AVERAGE(G15:I15),"") | K15: Prototype subtotal /70
A16: FINAL PRESENTATION / 30 | G16: =IF(G14="","",G14) | H16: =IF(H14="","",H14) | I16: =IF(I14="","",I14) | J16: =IF(COUNT(G16:I16)=3,AVERAGE(G16:I16),"") | K16: Presentation subtotal /30
A17: LECTURER TOTALS / 100 | G17: =IF(COUNT(G8:G14)=7,SUM(G8:G14),"") | H17: =IF(COUNT(H8:H14)=7,SUM(H8:H14),"") | I17: =IF(COUNT(I8:I14)=7,SUM(I8:I14),"") | J17: =IF(COUNT(G17:I17)=3,AVERAGE(G17:I17),"") | K17: Panel average /100
A18: FINAL PHASE 3 MARK / 50 | J18: =IF(J17="","",J17*50/100) | K18: /50
A21: Lecturer 1 Feedback | D21: Lecturer 2 Feedback | G21: Lecturer 3 Feedback | J21: Panel / Final Feedback
A28: Marking Status | B28: =IF(COUNT(G17:I17)=3,"Complete",COUNT(G17:I17)&"/3 lecturers complete") -> 0/3 lecturers complete | J28: Panel Date

Sheet Group I
A1: ITC327W | PHASE 3: FINAL PROTOTYPE | GROUP I
A3: Group | B3: Group I | E3: Project / Stakeholder
A4: Assessment | B4: Assessment 3 (50% of module) | E4: Group Members
A7: Assessment criterion | B7: Maximum | C7: Excellent | D7: Good | E7: Satisfactory | F7: Inadequate | G7: Lecturer 1 | H7: Lecturer 2 | I7: Lecturer 3 | J7: Panel Average | K7: Panel Comment
A8: Shared Supabase Backend | B8: 15 | C8: Database implements the approved ERD, appropriate keys and relationships, and required operations. Authentication and access controls work where required. Both apps use one shared Supabase project. | D8: Required database structure and shared services are implemented with minor omissions or errors. | E8: Basic backend works, but important tables, operations, permissions or relationships are incomplete. | F8: Backend is largely incomplete, unreliable or not shared by the two applications. | J8: =IF(COUNT(G8:I8)=3,AVERAGE(G8:I8),"")
A9: Flutter Mobile Application | B9: 15 | C9: Approved main screens, navigation, forms and functions work reliably and use Supabase. Access and user workflows follow the SRS. | D9: Most approved screens and functions work; minor gaps do not substantially affect the intended workflows. | E9: Some mobile screens and functions work, but several important requirements or backend operations remain incomplete. | F9: Mobile application cannot demonstrate its main approved functions or is largely incomplete. | J9: =IF(COUNT(G9:I9)=3,AVERAGE(G9:I9),"")
A10: ASP.NET Web Application | B10: 15 | C10: Approved main pages, navigation, forms and functions work reliably and use Supabase. Access and user workflows follow the SRS. | D10: Most approved pages and functions work; minor gaps do not substantially affect the intended workflows. | E10: Some web pages and functions work, but several important requirements or backend operations remain incomplete. | F10: Web application cannot demonstrate its main approved functions or is largely incomplete. | J10: =IF(COUNT(G10:I10)=3,AVERAGE(G10:I10),"")
A11: Integration and Functional Correctness | B11: 15 | C11: Both applications use the same Supabase records. At least two important approved shared processes work end to end, with consistent retrieval, updates and permitted access. | D11: Shared backend and two relevant processes are demonstrated, with minor inconsistencies or limitations. | E11: Integration is partly functional; one or more shared processes, updates or access rules have important gaps. | F11: Applications do not meaningfully share data or required integrated processes cannot be demonstrated. | J11: =IF(COUNT(G11:I11)=3,AVERAGE(G11:I11),"")
A12: Final SRS and Implementation Evidence | B12: 5 | C12: The existing SRS is continued with a clear implementation section, requirement-to-function status, appropriate screenshots, approved changes, known limitations, GitHub link and MS Project screenshot. | D12: Updated SRS and evidence are mostly complete, with minor gaps. | E12: Implementation section or evidence is incomplete; requirements and working status are only partly documented. | F12: Final SRS or important implementation evidence is largely absent or inaccurate. | J12: =IF(COUNT(G12:I12)=3,AVERAGE(G12:I12),"")
A13: Microsoft Project, GitHub and Progress Tracker | B13: 5 | C13: Editable schedule reflects actual progress; GitHub and submitted ZIP contain the demonstrated version with organised code and setup guidance; tracker records tasks, contributions, challenges and final group reflection. | D13: Project records and source code are current and generally organised, with minor gaps. | E13: Some required files or updates are present, but progress, contributions, version consistency or setup details are weak. | F13: Essential project records or source code are missing, inaccessible or do not represent the demonstrated version. | J13: =IF(COUNT(G13:I13)=3,AVERAGE(G13:I13),"")
A14: Final Presentation and Live Demonstration | B14: 30 | C14: Clear, organised live demonstration of the working Flutter, ASP.NET and Supabase solution, including at least two shared processes. Members participate meaningfully, explain decisions and limitations, and answer panel questions accurately. | D14: Main functions and shared processes are demonstrated clearly; explanations, participation and responses have only minor gaps. | E14: Demonstration shows some functionality but has important gaps in integration, clarity, participation or defence. | F14: Live demonstration does not show the essential working system, or the group cannot adequately explain its work. | J14: =IF(COUNT(G14:I14)=3,AVERAGE(G14:I14),"")
A15: PROTOTYPE AND PROJECT EVIDENCE / 70 | G15: =IF(COUNT(G8:G13)=6,SUM(G8:G13),"") | H15: =IF(COUNT(H8:H13)=6,SUM(H8:H13),"") | I15: =IF(COUNT(I8:I13)=6,SUM(I8:I13),"") | J15: =IF(COUNT(G15:I15)=3,AVERAGE(G15:I15),"") | K15: Prototype subtotal /70
